Workbook

Sheet 가이드 (먼저 읽기)
A1: 10/13 캠페인 분석 — 사용법 가이드
A3: 이 파일 구성
A4: · [10-13_원본데이터] 10/13 15:00~23:00, 481행 실측 원본
A5: · [분석_요약] 태그별 평균·표준편차·변동폭·변동%·상관계수·민감도가 '살아있는 수식'
A6: · [그래프] 전환율·큐멘·출구온도 vs 벤젠유량 산점도 + SP/PV 추종 그래프
A8: 이 캠페인이 실험한 것
A9: · 조작변수 = FC-1002.SP(벤젠 유량 설정값). 15000→12500→17500→15000 램프.
A10: · 비율 FRC-1004는 5.0 고정 → 벤젠↑이면 프로펜(FT-1004)도↑ → '총 공급유량'을 바꾸는 실험.
A11: · 즉 대회 케이스스터디 3변수 중 2) feed flow rate(공급유량) 효과를 보는 날.
A13: STEP 1 — 뭐가 움직이고 뭐가 안 움직이나
A14: · [분석_요약]는 |상관계수| 큰 순 정렬됨. '변동%'가 크면 크게 요동친 것.
A15: · '반응 여부' = 상관계수 0.5 이상이면 '반응함'. → TT-1001·TC-1205·LC-1212은 '거의 불변'(네 관찰과 일치).
... A41: · SP 17500 vs PV 최대 15357 → 벤젠 공급 포화.

Sheet 10-13_원본데이터
A1: Timestamp | B1: AT-1100.PV Value kg/m3 | C1: AT-1104.PV Value kg/m3 | D1: AT-1201.PV Value kg/m3 | E1: FC-1002.PV Value kg/h | F1: FC-1002.SP Value kg/h | G1: FRC-1004.PV Value | H1: FRC-1004.SP Value | I1: FT-1001.PV Value kg/h | J1: FT-1002.PV Value kg/h | K1: FT-1003.PV Value kg/h | L1: FT-1004.PV Value kg/h | M1: FT-1005.PV Value kg/h | N1: FT-1102.PV Value m3/h | O1: FT-1104.PV Value m3/h | P1: FT-1200.PV Value kg/h | Q1: FT-1201.PV Value kg/h | R1: FT-1215.PV Value kg/h | S1: FT-1300.PV Value kg/h | T1: LC-1001.PV Value % | U1: LC-1001.SP Value % | V1: LC-1104.PV Value % | W1: LC-1104.SP Value % | X1: LC-1200.PV Value % | Y1: LC-1200.SP Value % | Z1: LC-1212.PV Value % | AA1: LC-1212.SP Value % | AB1: PC-1104.PV Value kPa | AC1: PC-1104.SP Value kPa | AD1: PT-1001.PV Value kPa | AE1: PT-1004.PV Value kPa | AF1: PT-1100.PV Value kPa | AG1: PT-1300.PV Value kPa | AH1: TC-1006.PV Value °C | AI1: TC-1006.SP Value °C | AJ1: TC-1103.PV Value °C | AK1: TC-1103.SP Value °C | AL1: TC-1205.PV Value °C | AM1: TC-1205.SP Value °C | AN1: TC-1211.PV Value °C | AO1: TC-1211.SP Value °C | AP1: TC-1215.PV Value °C | AQ1: TC-1215.SP Value °C | AR1: TT-1001.PV Value °C | AS1: TT-1004.PV Value °C | AT1: TT-1005.PV Value °C | AU1: TT-1006.PV Value °C | AV1: TT-1100.PV Value °C | AW1: TT-1102.PV Value °C | AX1: TT-1103.PV Value °C | AY1: TT-1211.PV Value °C
A2: 15:00 | B2: 37.378 | C2: 797.951 | D2: 730.841 | E2: 15000 | F2: 15000 | G2: 5 | H2: 5 | I2: 5328.481 | J2: 15000 | K2: 15000 | L2: 3000 | M2: 26044.441 | N2: 420.016 | O2: 944.493 | P2: 14786.524 | Q2: 5115.005 | R2: 1477.199 | S2: 9671.519 | T2: 50 | U2: 50 | V2: 50 | W2: 50 | X2: 50 | Y2: 50 | Z2: 50 | AA2: 50 | AB2: 215.713 | AC2: 215.713 | AD2: 2623.925 | AE2: 2575.8 | AF2: 2521.58 | AG2: 2627.209 | AH2: 341.57 | AI2: 341.57 | AJ2: 90 | AK2: 90 | AL2: 151.419 | AM2: 151.419 | AN2: 40 | AO2: 40 | AP2: 104.581 | AQ2: 104.581 | AR2: 30.314 | AS2: 207.462 | AT2: 350 | AU2: 341.57 | AV2: 440.571 | AW2: 40.012 | AX2: 90 | AY2: 40
A3: 15:01 | B3: 37.378 | C3: 797.951 | D3: 730.841 | E3: 15000 | F3: 15000 | G3: 5 | H3: 5 | I3: 5328.481 | J3: 15000 | K3: 15000 | L3: 3000 | M3: 26044.441 | N3: 420.016 | O3: 944.493 | P3: 14786.524 | Q3: 5115.005 | R3: 1477.199 | S3: 9671.519 | T3: 50 | U3: 50 | V3: 50 | W3: 50 | X3: 50 | Y3: 50 | Z3: 50 | AA3: 50 | AB3: 215.713 | AC3: 215.713 | AD3: 2623.925 | AE3: 2575.8 | AF3: 2521.58 | AG3: 2627.209 | AH3: 341.57 | AI3: 341.57 | AJ3: 90 | AK3: 90 | AL3: 151.419 | AM3: 151.419 | AN3: 40 | AO3: 40 | AP3: 104.581 | AQ3: 104.581 | AR3: 30.314 | AS3: 207.462 | AT3: 350 | AU3: 341.57 | AV3: 440.571 | AW3: 40.012 | AX3: 90 | AY3: 40
A4: 15:02 | B4: 37.378 | C4: 797.951 | D4: 730.841 | E4: 15000 | F4: 15000 | G4: 5 | H4: 5 | I4: 5328.481 | J4: 15000 | K4: 15000 | L4: 3000 | M4: 26044.441 | N4: 420.016 | O4: 944.493 | P4: 14786.524 | Q4: 5115.005 | R4: 1477.199 | S4: 9671.519 | T4: 50 | U4: 50 | V4: 50 | W4: 50 | X4: 50 | Y4: 50 | Z4: 50 | AA4: 50 | AB4: 215.713 | AC4: 215.713 | AD4: 2623.925 | AE4: 2575.8 | AF4: 2521.58 | AG4: 2627.209 | AH4: 341.57 | AI4: 341.57 | AJ4: 90 | AK4: 90 | AL4: 151.419 | AM4: 151.419 | AN4: 40 | AO4: 40 | AP4: 104.581 | AQ4: 104.581 | AR4: 30.314 | AS4: 207.462 | AT4: 350 | AU4: 341.57 | AV4: 440.571 | AW4: 40.012 | AX4: 90 | AY4: 40
A5: 15:03 | B5: 37.378 | C5: 797.951 | D5: 730.841 | E5: 15000 | F5: 15000 | G5: 5 | H5: 5 | I5: 5328.481 | J5: 15000 | K5: 15000 | L5: 3000 | M5: 26044.441 | N5: 420.016 | O5: 944.493 | P5: 14786.524 | Q5: 5115.005 | R5: 1477.199 | S5: 9671.519 | T5: 50 | U5: 50 | V5: 50 | W5: 50 | X5: 50 | Y5: 50 | Z5: 50 | AA5: 50 | AB5: 215.713 | AC5: 215.713 | AD5: 2623.925 | AE5: 2575.8 | AF5: 2521.58 | AG5: 2627.209 | AH5: 341.57 | AI5: 341.57 | AJ5: 90 | AK5: 90 | AL5: 151.419 | AM5: 151.419 | AN5: 40 | AO5: 40 | AP5: 104.581 | AQ5: 104.581 | AR5: 30.314 | AS5: 207.462 | AT5: 350 | AU5: 341.57 | AV5: 440.571 | AW5: 40.012 | AX5: 90 | AY5: 40
A6: 15:04 | B6: 37.378 | C6: 797.951 | D6: 730.841 | E6: 15000 | F6: 15000 | G6: 5 | H6: 5 | I6: 5328.481 | J6: 15000 | K6: 15000 | L6: 3000 | M6: 26044.441 | N6: 420.016 | O6: 944.493 | P6: 14786.524 | Q6: 5115.005 | R6: 1477.199 | S6: 9671.519 | T6: 50 | U6: 50 | V6: 50 | W6: 50 | X6: 50 | Y6: 50 | Z6: 50 | AA6: 50 | AB6: 215.713 | AC6: 215.713 | AD6: 2623.925 | AE6: 2575.8 | AF6: 2521.58 | AG6: 2627.209 | AH6: 341.57 | AI6: 341.57 | AJ6: 90 | AK6: 90 | AL6: 151.419 | AM6: 151.419 | AN6: 40 | AO6: 40 | AP6: 104.581 | AQ6: 104.581 | AR6: 30.314 | AS6: 207.462 | AT6: 350 | AU6: 341.57 | AV6: 440.571 | AW6: 40.012 | AX6: 90 | AY6: 40
A7: 15:05 | B7: 37.378 | C7: 797.951 | D7: 730.841 | E7: 15000 | F7: 15000 | G7: 5 | H7: 5 | I7: 5328.481 | J7: 15000 | K7: 15000 | L7: 3000 | M7: 26044.441 | N7: 420.016 | O7: 944.493 | P7: 14786.524 | Q7: 5115.005 | R7: 1477.199 | S7: 9671.519 | T7: 50 | U7: 50 | V7: 50 | W7: 50 | X7: 50 | Y7: 50 | Z7: 50 | AA7: 50 | AB7: 215.713 | AC7: 215.713 | AD7: 2623.925 | AE7: 2575.8 | AF7: 2521.58 | AG7: 2627.209 | AH7: 341.57 | AI7: 341.57 | AJ7: 90 | AK7: 90 | AL7: 151.419 | AM7: 151.419 | AN7: 40 | AO7: 40 | AP7: 104.581 | AQ7: 104.581 | AR7: 30.314 | AS7: 207.462 | AT7: 350 | AU7: 341.57 | AV7: 440.571 | AW7: 40.012 | AX7: 90 | AY7: 40
A8: 15:06 | B8: 37.378 | C8: 797.951 | D8: 730.841 | E8: 15000 | F8: 15000 | G8: 5 | H8: 5 | I8: 5328.481 | J8: 15000 | K8: 15000 | L8: 3000 | M8: 26044.441 | N8: 420.016 | O8: 944.493 | P8: 14786.524 | Q8: 5115.005 | R8: 1477.199 | S8: 9671.519 | T8: 50 | U8: 50 | V8: 50 | W8: 50 | X8: 50 | Y8: 50 | Z8: 50 | AA8: 50 | AB8: 215.713 | AC8: 215.713 | AD8: 2623.925 | AE8: 2575.8 | AF8: 2521.58 | AG8: 2627.209 | AH8: 341.57 | AI8: 341.57 | AJ8: 90 | AK8: 90 | AL8: 151.419 | AM8: 151.419 | AN8: 40 | AO8: 40 | AP8: 104.581 | AQ8: 104.581 | AR8: 30.314 | AS8: 207.462 | AT8: 350 | AU8: 341.57 | AV8: 440.571 | AW8: 40.012 | AX8: 90 | AY8: 40
A9: 15:07 | B9: 37.378 | C9: 797.951 | D9: 730.841 | E9: 15000 | F9: 15000 | G9: 5 | H9: 5 | I9: 5328.481 | J9: 15000 | K9: 15000 | L9: 3000 | M9: 26044.441 | N9: 420.016 | O9: 944.493 | P9: 14786.524 | Q9: 5115.005 | R9: 1477.199 | S9: 9671.519 | T9: 50 | U9: 50 | V9: 50 | W9: 50 | X9: 50 | Y9: 50 | Z9: 50 | AA9: 50 | AB9: 215.713 | AC9: 215.713 | AD9: 2623.925 | AE9: 2575.8 | AF9: 2521.58 | AG9: 2627.209 | AH9: 341.57 | AI9: 341.57 | AJ9: 90 | AK9: 90 | AL9: 151.419 | AM9: 151.419 | AN9: 40 | AO9: 40 | AP9: 104.581 | AQ9: 104.581 | AR9: 30.314 | AS9: 207.462 | AT9: 350 | AU9: 341.57 | AV9: 440.571 | AW9: 40.012 | AX9: 90 | AY9: 40
A10: 15:08 | B10: 37.378 | C10: 797.951 | D10: 730.841 | E10: 15000 | F10: 15000 | G10: 5 | H10: 5 | I10: 5328.481 | J10: 15000 | K10: 15000 | L10: 3000 | M10: 26044.441 | N10: 420.016 | O10: 944.493 | P10: 14786.524 | Q10: 5115.005 | R10: 1477.199 | S10: 9671.519 | T10: 50 | U10: 50 | V10: 50 | W10: 50 | X10: 50 | Y10: 50 | Z10: 50 | AA10: 50 | AB10: 215.713 | AC10: 215.713 | AD10: 2623.925 | AE10: 2575.8 | AF10: 2521.58 | AG10: 2627.209 | AH10: 341.57 | AI10: 341.57 | AJ10: 90 | AK10: 90 | AL10: 151.419 | AM10: 151.419 | AN10: 40 | AO10: 40 | AP10: 104.581 | AQ10: 104.581 | AR10: 30.314 | AS10: 207.462 | AT10: 350 | AU10: 341.57 | AV10: 440.571 | AW10: 40.012 | AX10: 90 | AY10: 40
A11: 15:09 | B11: 37.378 | C11: 797.951 | D11: 730.841 | E11: 15000 | F11: 15000 | G11: 5 | H11: 5 | I11: 5328.481 | J11: 15000 | K11: 15000 | L11: 3000 | M11: 26044.441 | N11: 420.016 | O11: 944.493 | P11: 14786.524 | Q11: 5115.005 | R11: 1477.199 | S11: 9671.519 | T11: 50 | U11: 50 | V11: 50 | W11: 50 | X11: 50 | Y11: 50 | Z11: 50 | AA11: 50 | AB11: 215.713 | AC11: 215.713 | AD11: 2623.925 | AE11: 2575.8 | AF11: 2521.58 | AG11: 2627.209 | AH11: 341.57 | AI11: 341.57 | AJ11: 90 | AK11: 90 | AL11: 151.419 | AM11: 151.419 | AN11: 40 | AO11: 40 | AP11: 104.581 | AQ11: 104.581 | AR11: 30.314 | AS11: 207.462 | AT11: 350 | AU11: 341.57 | AV11: 440.571 | AW11: 40.012 | AX11: 90 | AY11: 40
A12: 15:10 | B12: 37.378 | C12: 797.951 | D12: 730.841 | E12: 15000 | F12: 15000 | G12: 5 | H12: 5 | I12: 5328.481 | J12: 15000 | K12: 15000 | L12: 3000 | M12: 26044.441 | N12: 420.016 | O12: 944.493 | P12: 14786.524 | Q12: 5115.005 | R12: 1477.199 | S12: 9671.519 | T12: 50 | U12: 50 | V12: 50 | W12: 50 | X12: 50 | Y12: 50 | Z12: 50 | AA12: 50 | AB12: 215.713 | AC12: 215.713 | AD12: 2623.925 | AE12: 2575.8 | AF12: 2521.58 | AG12: 2627.209 | AH12: 341.57 | AI12: 341.57 | AJ12: 90 | AK12: 90 | AL12: 151.419 | AM12: 151.419 | AN12: 40 | AO12: 40 | AP12: 104.581 | AQ12: 104.581 | AR12: 30.314 | AS12: 207.462 | AT12: 350 | AU12: 341.57 | AV12: 440.571 | AW12: 40.012 | AX12: 90 | AY12: 40
A13: 15:11 | B13: 37.378 | C13: 797.951 | D13: 730.841 | E13: 15000 | F13: 15000 | G13: 5 | H13: 5 | I13: 5328.481 | J13: 15000 | K13: 15000 | L13: 3000 | M13: 26044.441 | N13: 420.016 | O13: 944.493 | P13: 14786.524 | Q13: 5115.005 | R13: 1477.199 | S13: 9671.519 | T13: 50 | U13: 50 | V13: 50 | W13: 50 | X13: 50 | Y13: 50 | Z13: 50 | AA13: 50 | AB13: 215.713 | AC13: 215.713 | AD13: 2623.925 | AE13: 2575.8 | AF13: 2521.58 | AG13: 2627.209 | AH13: 341.57 | AI13: 341.57 | AJ13: 90 | AK13: 90 | AL13: 151.419 | AM13: 151.419 | AN13: 40 | AO13: 40 | AP13: 104.581 | AQ13: 104.581 | AR13: 30.314 | AS13: 207.462 | AT13: 350 | AU13: 341.57 | AV13: 440.571 | AW13: 40.012 | AX13: 90 | AY13: 40
... A482: 23:00 | B482: 37.391 | C482: 797.791 | D482: 730.851 | E482: 14999.759 | F482: 15000 | G482: 5 | H482: 5 | I482: 5708.258 | J482: 14999.759 | K482: 14999.759 | L482: 2999.871 | M482: 26178.51 | N482: 309.214 | O482: 952.897 | P482: 14580.21 | Q482: 5399.765 | R482: 1622.224 | S482: 9380.115 | T482: 46.426 | U482: 50 | V482: 48.997 | W482: 50 | X482: 52.362 | Y482: 50 | Z482: 50 | AA482: 50 | AB482: 210.205 | AC482: 215.713 | AD482: 2623.964 | AE482: 2574.824 | AF482: 2520.6 | AG482: 2627.053 | AH482: 342.021 | AI482: 341.57 | AJ482: 90.736 | AK482: 90 | AL482: 151.419 | AM482: 151.419 | AN482: 40.612 | AO482: 40 | AP482: 104.445 | AQ482: 104.581 | AR482: 30.314 | AS482: 207.457 | AT482: 351.097 | AU482: 342.021 | AV482: 442.495 | AW482: 43.622 | AX482: 90.736 | AY482: 40.612

Sheet 분석_요약
A1: ◆ 10/13 캠페인 분석 요약 — 조작변수: FC-1002.SP (벤젠 유량 설정값), 비율 FRC-1004는 5.0 고정
A2: (상관계수 큰 순 정렬. 값은 모두 살아있는 수식 — 셀 클릭하면 식이 보임)
A4: 태그 | B4: 한글 설명 | C4: 평균 | D4: 표준편차 | E4: 최소 | F4: 최대 | G4: 변동폭(최대-최소) | H4: 변동% | I4: FC-1002.PV와 상관계수 | J4: 민감도(기울기) | K4: 반응 여부
A5: FC-1002.PV Value kg/h | B5: 벤젠 유량 실측(제어 결과) | C5: =AVERAGE('10-13_원본데이터'!E2:E482) | D5: =STDEV('10-13_원본데이터'!E2:E482) | E5: =MIN('10-13_원본데이터'!E2:E482) | F5: =MAX('10-13_원본데이터'!E2:E482) | G5: =F5-E5 | H5: =IF(C5=0,0,G5/ABS(C5)*100) | I5: =IFERROR(CORREL('10-13_원본데이터'!E2:E482,'10-13_원본데이터'!E2:E482),"-") | J5: =IFERROR(SLOPE('10-13_원본데이터'!E2:E482,'10-13_원본데이터'!E2:E482),"-") | K5: =IF(H5>=0.5,"반응함","거의 불변")
A6: FT-1002.PV Value kg/h | B6: 벤젠 질량유량(재순환 포함) | C6: =AVERAGE('10-13_원본데이터'!J2:J482) | D6: =STDEV('10-13_원본데이터'!J2:J482) | E6: =MIN('10-13_원본데이터'!J2:J482) | F6: =MAX('10-13_원본데이터'!J2:J482) | G6: =F6-E6 | H6: =IF(C6=0,0,G6/ABS(C6)*100) | I6: =IFERROR(CORREL('10-13_원본데이터'!E2:E482,'10-13_원본데이터'!J2:J482),"-") | J6: =IFERROR(SLOPE('10-13_원본데이터'!J2:J482,'10-13_원본데이터'!E2:E482),"-") | K6: =IF(H6>=0.5,"반응함","거의 불변")
A7: FT-1003.PV Value kg/h | B7: 벤젠 질량유량(재순환 포함) | C7: =AVERAGE('10-13_원본데이터'!K2:K482) | D7: =STDEV('10-13_원본데이터'!K2:K482) | E7: =MIN('10-13_원본데이터'!K2:K482) | F7: =MAX('10-13_원본데이터'!K2:K482) | G7: =F7-E7 | H7: =IF(C7=0,0,G7/ABS(C7)*100) | I7: =IFERROR(CORREL('10-13_원본데이터'!E2:E482,'10-13_원본데이터'!K2:K482),"-") | J7: =IFERROR(SLOPE('10-13_원본데이터'!K2:K482,'10-13_원본데이터'!E2:E482),"-") | K7: =IF(H7>=0.5,"반응함","거의 불변")
A8: AT-1100.PV Value kg/m3 | B8: 반응기 출구 밀도 (*플랜트 없음, 전환율 라벨원) | C8: =AVERAGE('10-13_원본데이터'!B2:B482) | D8: =STDEV('10-13_원본데이터'!B2:B482) | E8: =MIN('10-13_원본데이터'!B2:B482) | F8: =MAX('10-13_원본데이터'!B2:B482) | G8: =F8-E8 | H8: =IF(C8=0,0,G8/ABS(C8)*100) | I8: =IFERROR(CORREL('10-13_원본데이터'!E2:E482,'10-13_원본데이터'!B2:B482),"-") | J8: =IFERROR(SLOPE('10-13_원본데이터'!B2:B482,'10-13_원본데이터'!E2:E482),"-") | K8: =IF(H8>=0.5,"반응함","거의 불변")
A9: PT-1100.PV Value kPa | B9: 반응기 출구 압력 | C9: =AVERAGE('10-13_원본데이터'!AF2:AF482) | D9: =STDEV('10-13_원본데이터'!AF2:AF482) | E9: =MIN('10-13_원본데이터'!AF2:AF482) | F9: =MAX('10-13_원본데이터'!AF2:AF482) | G9: =F9-E9 | H9: =IF(C9=0,0,G9/ABS(C9)*100) | I9: =IFERROR(CORREL('10-13_원본데이터'!E2:E482,'10-13_원본데이터'!AF2:AF482),"-") | J9: =IFERROR(SLOPE('10-13_원본데이터'!AF2:AF482,'10-13_원본데이터'!E2:E482),"-") | K9: =IF(H9>=0.5,"반응함","거의 불변")
A10: TT-1004.PV Value °C | B10: 프로펜 공급 온도 | C10: =AVERAGE('10-13_원본데이터'!AS2:AS482) | D10: =STDEV('10-13_원본데이터'!AS2:AS482) | E10: =MIN('10-13_원본데이터'!AS2:AS482) | F10: =MAX('10-13_원본데이터'!AS2:AS482) | G10: =F10-E10 | H10: =IF(C10=0,0,G10/ABS(C10)*100) | I10: =IFERROR(CORREL('10-13_원본데이터'!E2:E482,'10-13_원본데이터'!AS2:AS482),"-") | J10: =IFERROR(SLOPE('10-13_원본데이터'!AS2:AS482,'10-13_원본데이터'!E2:E482),"-") | K10: =IF(H10>=0.5,"반응함","거의 불변")
A11: PT-1004.PV Value kPa | B11: 프로펜 공급 압력 | C11: =AVERAGE('10-13_원본데이터'!AE2:AE482) | D11: =STDEV('10-13_원본데이터'!AE2:AE482) | E11: =MIN('10-13_원본데이터'!AE2:AE482) | F11: =MAX('10-13_원본데이터'!AE2:AE482) | G11: =F11-E11 | H11: =IF(C11=0,0,G11/ABS(C11)*100) | I11: =IFERROR(CORREL('10-13_원본데이터'!E2:E482,'10-13_원본데이터'!AE2:AE482),"-") | J11: =IFERROR(SLOPE('10-13_원본데이터'!AE2:AE482,'10-13_원본데이터'!E2:E482),"-") | K11: =IF(H11>=0.5,"반응함","거의 불변")
A12: FT-1004.PV Value kg/h | B12: 프로펜 공급 질량유량 | C12: =AVERAGE('10-13_원본데이터'!L2:L482) | D12: =STDEV('10-13_원본데이터'!L2:L482) | E12: =MIN('10-13_원본데이터'!L2:L482) | F12: =MAX('10-13_원본데이터'!L2:L482) | G12: =F12-E12 | H12: =IF(C12=0,0,G12/ABS(C12)*100) | I12: =IFERROR(CORREL('10-13_원본데이터'!E2:E482,'10-13_원본데이터'!L2:L482),"-") | J12: =IFERROR(SLOPE('10-13_원본데이터'!L2:L482,'10-13_원본데이터'!E2:E482),"-") | K12: =IF(H12>=0.5,"반응함","거의 불변")
A13: FT-1005.PV Value kg/h | B13: DOWTHERM 열매체 공급유량 | C13: =AVERAGE('10-13_원본데이터'!M2:M482) | D13: =STDEV('10-13_원본데이터'!M2:M482) | E13: =MIN('10-13_원본데이터'!M2:M482) | F13: =MAX('10-13_원본데이터'!M2:M482) | G13: =F13-E13 | H13: =IF(C13=0,0,G13/ABS(C13)*100) | I13: =IFERROR(CORREL('10-13_원본데이터'!E2:E482,'10-13_원본데이터'!M2:M482),"-") | J13: =IFERROR(SLOPE('10-13_원본데이터'!M2:M482,'10-13_원본데이터'!E2:E482),"-") | K13: =IF(H13>=0.5,"반응함","거의 불변")
A14: TT-1005.PV Value °C | B14: DOWTHERM 복귀 온도 | C14: =AVERAGE('10-13_원본데이터'!AT2:AT482) | D14: =STDEV('10-13_원본데이터'!AT2:AT482) | E14: =MIN('10-13_원본데이터'!AT2:AT482) | F14: =MAX('10-13_원본데이터'!AT2:AT482) | G14: =F14-E14 | H14: =IF(C14=0,0,G14/ABS(C14)*100) | I14: =IFERROR(CORREL('10-13_원본데이터'!E2:E482,'10-13_원본데이터'!AT2:AT482),"-") | J14: =IFERROR(SLOPE('10-13_원본데이터'!AT2:AT482,'10-13_원본데이터'!E2:E482),"-") | K14: =IF(H14>=0.5,"반응함","거의 불변")
A15: LC-1001.PV Value % | B15: 벤젠 공급탱크 레벨 | C15: =AVERAGE('10-13_원본데이터'!T2:T482) | D15: =STDEV('10-13_원본데이터'!T2:T482) | E15: =MIN('10-13_원본데이터'!T2:T482) | F15: =MAX('10-13_원본데이터'!T2:T482) | G15: =F15-E15 | H15: =IF(C15=0,0,G15/ABS(C15)*100) | I15: =IFERROR(CORREL('10-13_원본데이터'!E2:E482,'10-13_원본데이터'!T2:T482),"-") | J15: =IFERROR(SLOPE('10-13_원본데이터'!T2:T482,'10-13_원본데이터'!E2:E482),"-") | K15: =IF(H15>=0.5,"반응함","거의 불변")
A16: FT-1001.PV Value kg/h | B16: 신선 벤젠 질량유량 | C16: =AVERAGE('10-13_원본데이터'!I2:I482) | D16: =STDEV('10-13_원본데이터'!I2:I482) | E16: =MIN('10-13_원본데이터'!I2:I482) | F16: =MAX('10-13_원본데이터'!I2:I482) | G16: =F16-E16 | H16: =IF(C16=0,0,G16/ABS(C16)*100) | I16: =IFERROR(CORREL('10-13_원본데이터'!E2:E482,'10-13_원본데이터'!I2:I482),"-") | J16: =IFERROR(SLOPE('10-13_원본데이터'!I2:I482,'10-13_원본데이터'!E2:E482),"-") | K16: =IF(H16>=0.5,"반응함","거의 불변")
A17: PT-1001.PV Value kPa | B17: 신선 벤젠 압력 | C17: =AVERAGE('10-13_원본데이터'!AD2:AD482) | D17: =STDEV('10-13_원본데이터'!AD2:AD482) | E17: =MIN('10-13_원본데이터'!AD2:AD482) | F17: =MAX('10-13_원본데이터'!AD2:AD482) | G17: =F17-E17 | H17: =IF(C17=0,0,G17/ABS(C17)*100) | I17: =IFERROR(CORREL('10-13_원본데이터'!E2:E482,'10-13_원본데이터'!AD2:AD482),"-") | J17: =IFERROR(SLOPE('10-13_원본데이터'!AD2:AD482,'10-13_원본데이터'!E2:E482),"-") | K17: =IF(H17>=0.5,"반응함","거의 불변")
A18: FC-1002.SP Value kg/h | B18: ★조작변수★ 벤젠 유량 SP(설정값) | C18: =AVERAGE('10-13_원본데이터'!F2:F482) | D18: =STDEV('10-13_원본데이터'!F2:F482) | E18: =MIN('10-13_원본데이터'!F2:F482) | F18: =MAX('10-13_원본데이터'!F2:F482) | G18: =F18-E18 | H18: =IF(C18=0,0,G18/ABS(C18)*100) | I18: =IFERROR(CORREL('10-13_원본데이터'!E2:E482,'10-13_원본데이터'!F2:F482),"-") | J18: =IFERROR(SLOPE('10-13_원본데이터'!F2:F482,'10-13_원본데이터'!E2:E482),"-") | K18: =IF(H18>=0.5,"반응함","거의 불변")
A19: TC-1103.PV Value °C | B19: 제품냉각기 유틸 출구온도 | C19: =AVERAGE('10-13_원본데이터'!AJ2:AJ482) | D19: =STDEV('10-13_원본데이터'!AJ2:AJ482) | E19: =MIN('10-13_원본데이터'!AJ2:AJ482) | F19: =MAX('10-13_원본데이터'!AJ2:AJ482) | G19: =F19-E19 | H19: =IF(C19=0,0,G19/ABS(C19)*100) | I19: =IFERROR(CORREL('10-13_원본데이터'!E2:E482,'10-13_원본데이터'!AJ2:AJ482),"-") | J19: =IFERROR(SLOPE('10-13_원본데이터'!AJ2:AJ482,'10-13_원본데이터'!E2:E482),"-") | K19: =IF(H19>=0.5,"반응함","거의 불변")
A20: TT-1103.PV Value °C | B20: 제품 냉각기 후 온도 | C20: =AVERAGE('10-13_원본데이터'!AX2:AX482) | D20: =STDEV('10-13_원본데이터'!AX2:AX482) | E20: =MIN('10-13_원본데이터'!AX2:AX482) | F20: =MAX('10-13_원본데이터'!AX2:AX482) | G20: =F20-E20 | H20: =IF(C20=0,0,G20/ABS(C20)*100) | I20: =IFERROR(CORREL('10-13_원본데이터'!E2:E482,'10-13_원본데이터'!AX2:AX482),"-") | J20: =IFERROR(SLOPE('10-13_원본데이터'!AX2:AX482,'10-13_원본데이터'!E2:E482),"-") | K20: =IF(H20>=0.5,"반응함","거의 불변")
A21: PT-1300.PV Value kPa | B21: 벤젠 재순환 압력 | C21: =AVERAGE('10-13_원본데이터'!AG2:AG482) | D21: =STDEV('10-13_원본데이터'!AG2:AG482) | E21: =MIN('10-13_원본데이터'!AG2:AG482) | F21: =MAX('10-13_원본데이터'!AG2:AG482) | G21: =F21-E21 | H21: =IF(C21=0,0,G21/ABS(C21)*100) | I21: =IFERROR(CORREL('10-13_원본데이터'!E2:E482,'10-13_원본데이터'!AG2:AG482),"-") | J21: =IFERROR(SLOPE('10-13_원본데이터'!AG2:AG482,'10-13_원본데이터'!E2:E482),"-") | K21: =IF(H21>=0.5,"반응함","거의 불변")
A22: AT-1104.PV Value kg/m3 | B22: 컬럼 공급 밀도 (*플랜트 없음) | C22: =AVERAGE('10-13_원본데이터'!C2:C482) | D22: =STDEV('10-13_원본데이터'!C2:C482) | E22: =MIN('10-13_원본데이터'!C2:C482) | F22: =MAX('10-13_원본데이터'!C2:C482) | G22: =F22-E22 | H22: =IF(C22=0,0,G22/ABS(C22)*100) | I22: =IFERROR(CORREL('10-13_원본데이터'!E2:E482,'10-13_원본데이터'!C2:C482),"-") | J22: =IFERROR(SLOPE('10-13_원본데이터'!C2:C482,'10-13_원본데이터'!E2:E482),"-") | K22: =IF(H22>=0.5,"반응함","거의 불변")
A23: FT-1201.PV Value kg/h | B23: 큐멘 제품 질량유량 | C23: =AVERAGE('10-13_원본데이터'!Q2:Q482) | D23: =STDEV('10-13_원본데이터'!Q2:Q482) | E23: =MIN('10-13_원본데이터'!Q2:Q482) | F23: =MAX('10-13_원본데이터'!Q2:Q482) | G23: =F23-E23 | H23: =IF(C23=0,0,G23/ABS(C23)*100) | I23: =IFERROR(CORREL('10-13_원본데이터'!E2:E482,'10-13_원본데이터'!Q2:Q482),"-") | J23: =IFERROR(SLOPE('10-13_원본데이터'!Q2:Q482,'10-13_원본데이터'!E2:E482),"-") | K23: =IF(H23>=0.5,"반응함","거의 불변")
A24: AT-1201.PV Value kg/m3 | B24: 큐멘 제품 밀도 (*플랜트 없음) | C24: =AVERAGE('10-13_원본데이터'!D2:D482) | D24: =STDEV('10-13_원본데이터'!D2:D482) | E24: =MIN('10-13_원본데이터'!D2:D482) | F24: =MAX('10-13_원본데이터'!D2:D482) | G24: =F24-E24 | H24: =IF(C24=0,0,G24/ABS(C24)*100) | I24: =IFERROR(CORREL('10-13_원본데이터'!E2:E482,'10-13_원본데이터'!D2:D482),"-") | J24: =IFERROR(SLOPE('10-13_원본데이터'!D2:D482,'10-13_원본데이터'!E2:E482),"-") | K24: =IF(H24>=0.5,"반응함","거의 불변")
A25: FT-1200.PV Value kg/h | B25: 컬럼 공급 질량유량 | C25: =AVERAGE('10-13_원본데이터'!P2:P482) | D25: =STDEV('10-13_원본데이터'!P2:P482) | E25: =MIN('10-13_원본데이터'!P2:P482) | F25: =MAX('10-13_원본데이터'!P2:P482) | G25: =F25-E25 | H25: =IF(C25=0,0,G25/ABS(C25)*100) | I25: =IFERROR(CORREL('10-13_원본데이터'!E2:E482,'10-13_원본데이터'!P2:P482),"-") | J25: =IFERROR(SLOPE('10-13_원본데이터'!P2:P482,'10-13_원본데이터'!E2:E482),"-") | K25: =IF(H25>=0.5,"반응함","거의 불변")
A26: TC-1215.PV Value °C | B26: 컬럼 하부온도(stage3) | C26: =AVERAGE('10-13_원본데이터'!AP2:AP482) | D26: =STDEV('10-13_원본데이터'!AP2:AP482) | E26: =MIN('10-13_원본데이터'!AP2:AP482) | F26: =MAX('10-13_원본데이터'!AP2:AP482) | G26: =F26-E26 | H26: =IF(C26=0,0,G26/ABS(C26)*100) | I26: =IFERROR(CORREL('10-13_원본데이터'!E2:E482,'10-13_원본데이터'!AP2:AP482),"-") | J26: =IFERROR(SLOPE('10-13_원본데이터'!AP2:AP482,'10-13_원본데이터'!E2:E482),"-") | K26: =IF(H26>=0.5,"반응함","거의 불변")
A27: TC-1211.PV Value °C | B27: 컬럼 상부온도 | C27: =AVERAGE('10-13_원본데이터'!AN2:AN482) | D27: =STDEV('10-13_원본데이터'!AN2:AN482) | E27: =MIN('10-13_원본데이터'!AN2:AN482) | F27: =MAX('10-13_원본데이터'!AN2:AN482) | G27: =F27-E27 | H27: =IF(C27=0,0,G27/ABS(C27)*100) | I27: =IFERROR(CORREL('10-13_원본데이터'!E2:E482,'10-13_원본데이터'!AN2:AN482),"-") | J27: =IFERROR(SLOPE('10-13_원본데이터'!AN2:AN482,'10-13_원본데이터'!E2:E482),"-") | K27: =IF(H27>=0.5,"반응함","거의 불변")
A28: TT-1211.PV Value °C | B28: 컬럼 상부 온도 | C28: =AVERAGE('10-13_원본데이터'!AY2:AY482) | D28: =STDEV('10-13_원본데이터'!AY2:AY482) | E28: =MIN('10-13_원본데이터'!AY2:AY482) | F28: =MAX('10-13_원본데이터'!AY2:AY482) | G28: =F28-E28 | H28: =IF(C28=0,0,G28/ABS(C28)*100) | I28: =IFERROR(CORREL('10-13_원본데이터'!E2:E482,'10-13_원본데이터'!AY2:AY482),"-") | J28: =IFERROR(SLOPE('10-13_원본데이터'!AY2:AY482,'10-13_원본데이터'!E2:E482),"-") | K28: =IF(H28>=0.5,"반응함","거의 불변")
A29: TT-1100.PV Value °C | B29: 반응기 출구 온도 | C29: =AVERAGE('10-13_원본데이터'!AV2:AV482) | D29: =STDEV('10-13_원본데이터'!AV2:AV482) | E29: =MIN('10-13_원본데이터'!AV2:AV482) | F29: =MAX('10-13_원본데이터'!AV2:AV482) | G29: =F29-E29 | H29: =IF(C29=0,0,G29/ABS(C29)*100) | I29: =IFERROR(CORREL('10-13_원본데이터'!E2:E482,'10-13_원본데이터'!AV2:AV482),"-") | J29: =IFERROR(SLOPE('10-13_원본데이터'!AV2:AV482,'10-13_원본데이터'!E2:E482),"-") | K29: =IF(H29>=0.5,"반응함","거의 불변")
A30: FT-1215.PV Value kg/h | B30: 컬럼 재순환 질량유량 | C30: =AVERAGE('10-13_원본데이터'!R2:R482) | D30: =STDEV('10-13_원본데이터'!R2:R482) | E30: =MIN('10-13_원본데이터'!R2:R482) | F30: =MAX('10-13_원본데이터'!R2:R482) | G30: =F30-E30 | H30: =IF(C30=0,0,G30/ABS(C30)*100) | I30: =IFERROR(CORREL('10-13_원본데이터'!E2:E482,'10-13_원본데이터'!R2:R482),"-") | J30: =IFERROR(SLOPE('10-13_원본데이터'!R2:R482,'10-13_원본데이터'!E2:E482),"-") | K30: =IF(H30>=0.5,"반응함","거의 불변")
A31: LC-1104.PV Value % | B31: 플래시드럼 레벨 | C31: =AVERAGE('10-13_원본데이터'!V2:V482) | D31: =STDEV('10-13_원본데이터'!V2:V482) | E31: =MIN('10-13_원본데이터'!V2:V482) | F31: =MAX('10-13_원본데이터'!V2:V482) | G31: =F31-E31 | H31: =IF(C31=0,0,G31/ABS(C31)*100) | I31: =IFERROR(CORREL('10-13_원본데이터'!E2:E482,'10-13_원본데이터'!V2:V482),"-") | J31: =IFERROR(SLOPE('10-13_원본데이터'!V2:V482,'10-13_원본데이터'!E2:E482),"-") | K31: =IF(H31>=0.5,"반응함","거의 불변")
A32: FT-1104.PV Value m3/h | B32: 벤트가스 체적유량 | C32: =AVERAGE('10-13_원본데이터'!O2:O482) | D32: =STDEV('10-13_원본데이터'!O2:O482) | E32: =MIN('10-13_원본데이터'!O2:O482) | F32: =MAX('10-13_원본데이터'!O2:O482) | G32: =F32-E32 | H32: =IF(C32=0,0,G32/ABS(C32)*100) | I32: =IFERROR(CORREL('10-13_원본데이터'!E2:E482,'10-13_원본데이터'!O2:O482),"-") | J32: =IFERROR(SLOPE('10-13_원본데이터'!O2:O482,'10-13_원본데이터'!E2:E482),"-") | K32: =IF(H32>=0.5,"반응함","거의 불변")
A33: TT-1001.PV Value °C | B33: 신선 벤젠 온도 | C33: =AVERAGE('10-13_원본데이터'!AR2:AR482) | D33: =STDEV('10-13_원본데이터'!AR2:AR482) | E33: =MIN('10-13_원본데이터'!AR2:AR482) | F33: =MAX('10-13_원본데이터'!AR2:AR482) | G33: =F33-E33 | H33: =IF(C33=0,0,G33/ABS(C33)*100) | I33: =IFERROR(CORREL('10-13_원본데이터'!E2:E482,'10-13_원본데이터'!AR2:AR482),"-") | J33: =IFERROR(SLOPE('10-13_원본데이터'!AR2:AR482,'10-13_원본데이터'!E2:E482),"-") | K33: =IF(H33>=0.5,"반응함","거의 불변")
A34: TT-1102.PV Value °C | B34: 냉각수 복귀 온도 | C34: =AVERAGE('10-13_원본데이터'!AW2:AW482) | D34: =STDEV('10-13_원본데이터'!AW2:AW482) | E34: =MIN('10-13_원본데이터'!AW2:AW482) | F34: =MAX('10-13_원본데이터'!AW2:AW482) | G34: =F34-E34 | H34: =IF(C34=0,0,G34/ABS(C34)*100) | I34: =IFERROR(CORREL('10-13_원본데이터'!E2:E482,'10-13_원본데이터'!AW2:AW482),"-") | J34: =IFERROR(SLOPE('10-13_원본데이터'!AW2:AW482,'10-13_원본데이터'!E2:E482),"-") | K34: =IF(H34>=0.5,"반응함","거의 불변")
A35: FT-1300.PV Value kg/h | B35: 벤젠 재순환 질량유량 | C35: =AVERAGE('10-13_원본데이터'!S2:S482) | D35: =STDEV('10-13_원본데이터'!S2:S482) | E35: =MIN('10-13_원본데이터'!S2:S482) | F35: =MAX('10-13_원본데이터'!S2:S482) | G35: =F35-E35 | H35: =IF(C35=0,0,G35/ABS(C35)*100) | I35: =IFERROR(CORREL('10-13_원본데이터'!E2:E482,'10-13_원본데이터'!S2:S482),"-") | J35: =IFERROR(SLOPE('10-13_원본데이터'!S2:S482,'10-13_원본데이터'!E2:E482),"-") | K35: =IF(H35>=0.5,"반응함","거의 불변")
A36: FT-1102.PV Value m3/h | B36: 냉각수 체적유량 | C36: =AVERAGE('10-13_원본데이터'!N2:N482) | D36: =STDEV('10-13_원본데이터'!N2:N482) | E36: =MIN('10-13_원본데이터'!N2:N482) | F36: =MAX('10-13_원본데이터'!N2:N482) | G36: =F36-E36 | H36: =IF(C36=0,0,G36/ABS(C36)*100) | I36: =IFERROR(CORREL('10-13_원본데이터'!E2:E482,'10-13_원본데이터'!N2:N482),"-") | J36: =IFERROR(SLOPE('10-13_원본데이터'!N2:N482,'10-13_원본데이터'!E2:E482),"-") | K36: =IF(H36>=0.5,"반응함","거의 불변")
A37: PC-1104.PV Value kPa | B37: 플래시드럼 압력 | C37: =AVERAGE('10-13_원본데이터'!AB2:AB482) | D37: =STDEV('10-13_원본데이터'!AB2:AB482) | E37: =MIN('10-13_원본데이터'!AB2:AB482) | F37: =MAX('10-13_원본데이터'!AB2:AB482) | G37: =F37-E37 | H37: =IF(C37=0,0,G37/ABS(C37)*100) | I37: =IFERROR(CORREL('10-13_원본데이터'!E2:E482,'10-13_원본데이터'!AB2:AB482),"-") | J37: =IFERROR(SLOPE('10-13_원본데이터'!AB2:AB482,'10-13_원본데이터'!E2:E482),"-") | K37: =IF(H37>=0.5,"반응함","거의 불변")
A38: TC-1006.PV Value °C | B38: 반응기 입구온도 | C38: =AVERAGE('10-13_원본데이터'!AH2:AH482) | D38: =STDEV('10-13_원본데이터'!AH2:AH482) | E38: =MIN('10-13_원본데이터'!AH2:AH482) | F38: =MAX('10-13_원본데이터'!AH2:AH482) | G38: =F38-E38 | H38: =IF(C38=0,0,G38/ABS(C38)*100) | I38: =IFERROR(CORREL('10-13_원본데이터'!E2:E482,'10-13_원본데이터'!AH2:AH482),"-") | J38: =IFERROR(SLOPE('10-13_원본데이터'!AH2:AH482,'10-13_원본데이터'!E2:E482),"-") | K38: =IF(H38>=0.5,"반응함","거의 불변")
A39: TT-1006.PV Value °C | B39: 반응기 입구 온도 | C39: =AVERAGE('10-13_원본데이터'!AU2:AU482) | D39: =STDEV('10-13_원본데이터'!AU2:AU482) | E39: =MIN('10-13_원본데이터'!AU2:AU482) | F39: =MAX('10-13_원본데이터'!AU2:AU482) | G39: =F39-E39 | H39: =IF(C39=0,0,G39/ABS(C39)*100) | I39: =IFERROR(CORREL('10-13_원본데이터'!E2:E482,'10-13_원본데이터'!AU2:AU482),"-") | J39: =IFERROR(SLOPE('10-13_원본데이터'!AU2:AU482,'10-13_원본데이터'!E2:E482),"-") | K39: =IF(H39>=0.5,"반응함","거의 불변")
A40: LC-1200.PV Value % | B40: 컬럼 섬프 레벨 | C40: =AVERAGE('10-13_원본데이터'!X2:X482) | D40: =STDEV('10-13_원본데이터'!X2:X482) | E40: =MIN('10-13_원본데이터'!X2:X482) | F40: =MAX('10-13_원본데이터'!X2:X482) | G40: =F40-E40 | H40: =IF(C40=0,0,G40/ABS(C40)*100) | I40: =IFERROR(CORREL('10-13_원본데이터'!E2:E482,'10-13_원본데이터'!X2:X482),"-") | J40: =IFERROR(SLOPE('10-13_원본데이터'!X2:X482,'10-13_원본데이터'!E2:E482),"-") | K40: =IF(H40>=0.5,"반응함","거의 불변")
A41: FRC-1004.PV Value | B41: 벤젠/프로펜 비율 실측(≈5 고정) | C41: =AVERAGE('10-13_원본데이터'!G2:G482) | D41: =STDEV('10-13_원본데이터'!G2:G482) | E41: =MIN('10-13_원본데이터'!G2:G482) | F41: =MAX('10-13_원본데이터'!G2:G482) | G41: =F41-E41 | H41: =IF(C41=0,0,G41/ABS(C41)*100) | I41: =IFERROR(CORREL('10-13_원본데이터'!E2:E482,'10-13_원본데이터'!G2:G482),"-") | J41: =IFERROR(SLOPE('10-13_원본데이터'!G2:G482,'10-13_원본데이터'!E2:E482),"-") | K41: =IF(H41>=0.5,"반응함","거의 불변")
...

Sheet 그래프
A40: ※ SP는 17,500까지 오르지만 PV(실측)는 ~15,357에서 멈춤 → 벤젠 공급 포화(제어 한계).
